Process Process-3:
Traceback (most recent call last):
  File "/usr/lib/python3.5/multiprocessing/process.py", line 249, in _bootstrap
    self.run()
  File "/usr/lib/python3.5/multiprocessing/process.py", line 93, in run
    self._target(*self._args, **self._kwargs)
  File "/var/spool/slurmd/job94567/slurm_script", line 52, in mp_worker
    run_experiment(dim, n_train, train_seed, loss_fn, 0, checkpoint_dir, fn_pred=fn_pred, iterations=50000)
NameError: name 'run_experiment' is not defined
Process Process-2:
Traceback (most recent call last):
  File "/usr/lib/python3.5/multiprocessing/process.py", line 249, in _bootstrap
    self.run()
  File "/usr/lib/python3.5/multiprocessing/process.py", line 93, in run
    self._target(*self._args, **self._kwargs)
  File "/var/spool/slurmd/job94567/slurm_script", line 52, in mp_worker
    run_experiment(dim, n_train, train_seed, loss_fn, 0, checkpoint_dir, fn_pred=fn_pred, iterations=50000)
NameError: name 'run_experiment' is not defined
Process Process-4:
Traceback (most recent call last):
  File "/usr/lib/python3.5/multiprocessing/process.py", line 249, in _bootstrap
    self.run()
  File "/usr/lib/python3.5/multiprocessing/process.py", line 93, in run
    self._target(*self._args, **self._kwargs)
  File "/var/spool/slurmd/job94567/slurm_script", line 52, in mp_worker
    run_experiment(dim, n_train, train_seed, loss_fn, 0, checkpoint_dir, fn_pred=fn_pred, iterations=50000)
NameError: name 'run_experiment' is not defined
Process Process-1:
Traceback (most recent call last):
  File "/usr/lib/python3.5/multiprocessing/process.py", line 249, in _bootstrap
    self.run()
  File "/usr/lib/python3.5/multiprocessing/process.py", line 93, in run
    self._target(*self._args, **self._kwargs)
  File "/var/spool/slurmd/job94567/slurm_script", line 52, in mp_worker
    run_experiment(dim, n_train, train_seed, loss_fn, 0, checkpoint_dir, fn_pred=fn_pred, iterations=50000)
NameError: name 'run_experiment' is not defined
